Workbook

Sheet Cash Flow
A1: CASH FLOW STATEMENT
A2: 2018–2025 history · 2026–2032 forecasts
A4: PERIOD | B4: 2018A | C4: 2019A | D4: 2020A | E4: 2021A | F4: 2022A | G4: 2023A | H4: 2024A | I4: 2025A | J4: 2026E (9A+3F) | K4: 2027F | L4: 2028F | M4: 2029F | N4: 2030F | O4: 2031F | P4: 2032F
A5: FISCAL YEAR | B5: 2018 | C5: 2019 | D5: 2020 | E5: 2021 | F5: 2022 | G5: 2023 | H5: 2024 | I5: 2025 | J5: 2026 | K5: 2027 | L5: 2028 | M5: 2029 | N5: 2030 | O5: 2031 | P5: 2032
A7: CASH FROM OPERATING ACTIVITIES
A8: Net income / (loss) | B8: ='Income Statement'!B36 -> -1920000 | C8: ='Income Statement'!C36 -> -2650000 | D8: ='Income Statement'!D36 -> -4300000 | E8: ='Income Statement'!E36 -> -5682000 | F8: ='Income Statement'!F36 -> -21085000 | G8: ='Income Statement'!G36 -> -40000000 | H8: ='Income Statement'!H36 -> -62437500 | I8: ='Income Statement'!I36 -> -90065000 | ... P8: ='Income Statement'!P36 -> -104128599
A9: Add: depreciation and amortization | B9: ='Income Statement'!B27 -> 30000 | C9: ='Income Statement'!C27 -> 120000 | D9: ='Income Statement'!D27 -> 240000 | E9: ='Income Statement'!E27 -> 450000 | F9: ='Income Statement'!F27 -> 1100000 | G9: ='Income Statement'!G27 -> 3000000 | H9: ='Income Statement'!H27 -> 5000000 | I9: ='Income Statement'!I27 -> 7000000 | ... P9: ='Income Statement'!P27 -> 55062814
A10: Add: noncash stock-based compensation | B10: ='Income Statement'!B26 -> 40000 | C10: ='Income Statement'!C26 -> 100000 | D10: ='Income Statement'!D26 -> 240000 | E10: ='Income Statement'!E26 -> 450000 | F10: ='Income Statement'!F26 -> 750000 | G10: ='Income Statement'!G26 -> 2000000 | H10: ='Income Statement'!H26 -> 4000000 | I10: ='Income Statement'!I26 -> 7000000 | ... P10: ='Income Statement'!P26 -> 36669490
A11: Change in accounts receivable | B11: =-('Balance Sheet'!B9-0) -> 0 | C11: =-('Balance Sheet'!C9-'Balance Sheet'!B9) -> -43836 | D11: =-('Balance Sheet'!D9-'Balance Sheet'!C9) -> -98630 | E11: =-('Balance Sheet'!E9-'Balance Sheet'!D9) -> -202739 | F11: =-('Balance Sheet'!F9-'Balance Sheet'!E9) -> -394521 | G11: =-('Balance Sheet'!G9-'Balance Sheet'!F9) -> -1495890 | H11: =-('Balance Sheet'!H9-'Balance Sheet'!G9) -> -4745206 | I11: =-('Balance Sheet'!I9-'Balance Sheet'!H9) -> -7441096 | J11: =-('Balance Sheet'!J9-'Balance Sheet'!I9) -> -5872874 | ... P11: =-('Balance Sheet'!P9-'Balance Sheet'!O9) -> -9095031
A12: Change in inventory | B12: =-('Balance Sheet'!B10-0) -> 0 | C12: =-('Balance Sheet'!C10-'Balance Sheet'!B10) -> 0 | D12: =-('Balance Sheet'!D10-'Balance Sheet'!C10) -> 0 | E12: =-('Balance Sheet'!E10-'Balance Sheet'!D10) -> 0 | F12: =-('Balance Sheet'!F10-'Balance Sheet'!E10) -> 0 | G12: =-('Balance Sheet'!G10-'Balance Sheet'!F10) -> 0 | H12: =-('Balance Sheet'!H10-'Balance Sheet'!G10) -> -2591600 | I12: =-('Balance Sheet'!I10-'Balance Sheet'!H10) -> -3648400 | J12: =-('Balance Sheet'!J10-'Balance Sheet'!I10) -> -2572626 | ... P12: =-('Balance Sheet'!P10-'Balance Sheet'!O10) -> -6561095
A13: Change in prepaid expenses | B13: =-('Balance Sheet'!B11-0) -> 0 | C13: =-('Balance Sheet'!C11-'Balance Sheet'!B11) -> -20000 | D13: =-('Balance Sheet'!D11-'Balance Sheet'!C11) -> -45000 | E13: =-('Balance Sheet'!E11-'Balance Sheet'!D11) -> -85000 | F13: =-('Balance Sheet'!F11-'Balance Sheet'!E11) -> -210000 | G13: =-('Balance Sheet'!G11-'Balance Sheet'!F11) -> -660000 | H13: =-('Balance Sheet'!H11-'Balance Sheet'!G11) -> -1920000 | I13: =-('Balance Sheet'!I11-'Balance Sheet'!H11) -> -2700000 | J13: =-('Balance Sheet'!J11-'Balance Sheet'!I11) -> -2296713 | ... P13: =-('Balance Sheet'!P11-'Balance Sheet'!O11) -> -1110672
A14: Change in accounts payable | B14: ='Balance Sheet'!B17-0 -> 9452 | C14: ='Balance Sheet'!C17-'Balance Sheet'!B17 -> 26747 | D14: ='Balance Sheet'!D17-'Balance Sheet'!C17 -> 75582 | E14: ='Balance Sheet'!E17-'Balance Sheet'!D17 -> 98411 | F14: ='Balance Sheet'!F17-'Balance Sheet'!E17 -> 535698 | G14: ='Balance Sheet'!G17-'Balance Sheet'!F17 -> 601644 | H14: ='Balance Sheet'!H17-'Balance Sheet'!G17 -> 2178110 | I14: ='Balance Sheet'!I17-'Balance Sheet'!H17 -> 2657808 | J14: ='Balance Sheet'!J17-'Balance Sheet'!I17 -> 2860156 | ... P14: ='Balance Sheet'!P17-'Balance Sheet'!O17 -> 3413623
A15: Change in accrued expenses | B15: ='Balance Sheet'!B18-0 -> 92500 | C15: ='Balance Sheet'!C18-'Balance Sheet'!B18 -> 69500 | D15: ='Balance Sheet'!D18-'Balance Sheet'!C18 -> 163500 | E15: ='Balance Sheet'!E18-'Balance Sheet'!D18 -> 210500 | F15: ='Balance Sheet'!F18-'Balance Sheet'!E18 -> 1664000 | G15: ='Balance Sheet'!G18-'Balance Sheet'!F18 -> 2100000 | H15: ='Balance Sheet'!H18-'Balance Sheet'!G18 -> 4205000 | I15: ='Balance Sheet'!I18-'Balance Sheet'!H18 -> 6235000 | J15: ='Balance Sheet'!J18-'Balance Sheet'!I18 -> 5369630 | ... P15: ='Balance Sheet'!P18-'Balance Sheet'!O18 -> 5391922
A16: Change in deferred revenue | B16: ='Balance Sheet'!B19-0 -> 0 | C16: ='Balance Sheet'!C19-'Balance Sheet'!B19 -> 40000 | D16: ='Balance Sheet'!D19-'Balance Sheet'!C19 -> 116000 | E16: ='Balance Sheet'!E19-'Balance Sheet'!D19 -> 324000 | F16: ='Balance Sheet'!F19-'Balance Sheet'!E19 -> 840000 | G16: ='Balance Sheet'!G19-'Balance Sheet'!F19 -> 2420000 | H16: ='Balance Sheet'!H19-'Balance Sheet'!G19 -> 2200000 | I16: ='Balance Sheet'!I19-'Balance Sheet'!H19 -> 1020000 | J16: ='Balance Sheet'!J19-'Balance Sheet'!I19 -> 1566872 | ... P16: ='Balance Sheet'!P19-'Balance Sheet'!O19 -> 417833
A17: NET CASH FROM OPERATIONS | B17: =SUM(B8:B16) -> -1748048 | C17: =SUM(C8:C16) -> -2357589 | D17: =SUM(D8:D16) -> -3608548 | E17: =SUM(E8:E16) -> -4436828 | F17: =SUM(F8:F16) -> -16799823 | G17: =SUM(G8:G16) -> -32034246 | H17: =SUM(H8:H16) -> -54111196 | I17: =SUM(I8:I16) -> -79941688 | ... P17: =SUM(P8:P16) -> -19939715
A19: CASH FROM INVESTING ACTIVITIES
A20: Capital expenditures | B20: =-SUMIF('Monthly Data'!$B$2:$B1000,B$5,'Monthly Data'!$T$2:$T1000) -> -350000 | C20: =-SUMIF('Monthly Data'!$B$2:$B1000,C$5,'Monthly Data'!$T$2:$T1000) -> -750000 | D20: =-SUMIF('Monthly Data'!$B$2:$B1000,D$5,'Monthly Data'!$T$2:$T1000) -> -1250000 | E20: =-SUMIF('Monthly Data'!$B$2:$B1000,E$5,'Monthly Data'!$T$2:$T1000) -> -2500000 | F20: =-SUMIF('Monthly Data'!$B$2:$B1000,F$5,'Monthly Data'!$T$2:$T1000) -> -3000000 | G20: =-SUMIF('Monthly Data'!$B$2:$B1000,G$5,'Monthly Data'!$T$2:$T1000) -> -6000000 | H20: =-SUMIF('Monthly Data'!$B$2:$B1000,H$5,'Monthly Data'!$T$2:$T1000) -> -12000000 | I20: =-SUMIF('Monthly Data'!$B$2:$B1000,I$5,'Monthly Data'!$T$2:$T1000) -> -16000000 | ... P20: =-SUMIF('Monthly Data'!$B$2:$B1000,P$5,'Monthly Data'!$T$2:$T1000) -> -120279954
A21: NET CASH FROM INVESTING | B21: =B20 -> -350000 | C21: =C20 -> -750000 | D21: =D20 -> -1250000 | E21: =E20 -> -2500000 | F21: =F20 -> -3000000 | G21: =G20 -> -6000000 | H21: =H20 -> -12000000 | I21: =I20 -> -16000000 | ... P21: =P20 -> -120279954
A23: CASH FROM FINANCING ACTIVITIES
A24: Proceeds from equity financing | B24: =SUMIF('Monthly Data'!$B$2:$B1000,B$5,'Monthly Data'!$U$2:$U1000) -> 6000000 | C24: =SUMIF('Monthly Data'!$B$2:$B1000,C$5,'Monthly Data'!$U$2:$U1000) -> 0 | D24: =SUMIF('Monthly Data'!$B$2:$B1000,D$5,'Monthly Data'!$U$2:$U1000) -> 24000000 | E24: =SUMIF('Monthly Data'!$B$2:$B1000,E$5,'Monthly Data'!$U$2:$U1000) -> 0 | F24: =SUMIF('Monthly Data'!$B$2:$B1000,F$5,'Monthly Data'!$U$2:$U1000) -> 60000000 | G24: =SUMIF('Monthly Data'!$B$2:$B1000,G$5,'Monthly Data'!$U$2:$U1000) -> 0 | H24: =SUMIF('Monthly Data'!$B$2:$B1000,H$5,'Monthly Data'!$U$2:$U1000) -> 110000000 | I24: =SUMIF('Monthly Data'!$B$2:$B1000,I$5,'Monthly Data'!$U$2:$U1000) -> 0 | ... P24: =SUMIF('Monthly Data'!$B$2:$B1000,P$5,'Monthly Data'!$U$2:$U1000) -> 0
A25: Proceeds from venture debt | B25: =SUMIF('Monthly Data'!$B$2:$B1000,B$5,'Monthly Data'!$V$2:$V1000) -> 0 | C25: =SUMIF('Monthly Data'!$B$2:$B1000,C$5,'Monthly Data'!$V$2:$V1000) -> 0 | D25: =SUMIF('Monthly Data'!$B$2:$B1000,D$5,'Monthly Data'!$V$2:$V1000) -> 0 | E25: =SUMIF('Monthly Data'!$B$2:$B1000,E$5,'Monthly Data'!$V$2:$V1000) -> 0 | F25: =SUMIF('Monthly Data'!$B$2:$B1000,F$5,'Monthly Data'!$V$2:$V1000) -> 22000000 | G25: =SUMIF('Monthly Data'!$B$2:$B1000,G$5,'Monthly Data'!$V$2:$V1000) -> 40000000 | H25: =SUMIF('Monthly Data'!$B$2:$B1000,H$5,'Monthly Data'!$V$2:$V1000) -> 0 | I25: =SUMIF('Monthly Data'!$B$2:$B1000,I$5,'Monthly Data'!$V$2:$V1000) -> 40000000 | ... P25: =SUMIF('Monthly Data'!$B$2:$B1000,P$5,'Monthly Data'!$V$2:$V1000) -> 0
A26: Debt principal repayments | B26: =-SUMIF('Monthly Data'!$B$2:$B1000,B$5,'Monthly Data'!$W$2:$W1000) -> 0 | C26: =-SUMIF('Monthly Data'!$B$2:$B1000,C$5,'Monthly Data'!$W$2:$W1000) -> 0 | D26: =-SUMIF('Monthly Data'!$B$2:$B1000,D$5,'Monthly Data'!$W$2:$W1000) -> 0 | E26: =-SUMIF('Monthly Data'!$B$2:$B1000,E$5,'Monthly Data'!$W$2:$W1000) -> 0 | F26: =-SUMIF('Monthly Data'!$B$2:$B1000,F$5,'Monthly Data'!$W$2:$W1000) -> 0 | G26: =-SUMIF('Monthly Data'!$B$2:$B1000,G$5,'Monthly Data'!$W$2:$W1000) -> 0 | H26: =-SUMIF('Monthly Data'!$B$2:$B1000,H$5,'Monthly Data'!$W$2:$W1000) -> -5000000 | I26: =-SUMIF('Monthly Data'!$B$2:$B1000,I$5,'Monthly Data'!$W$2:$W1000) -> 0 | ... P26: =-SUMIF('Monthly Data'!$B$2:$B1000,P$5,'Monthly Data'!$W$2:$W1000) -> -15000000
A27: NET CASH FROM FINANCING | B27: =SUM(B24:B26) -> 6000000 | C27: =SUM(C24:C26) -> 0 | D27: =SUM(D24:D26) -> 24000000 | E27: =SUM(E24:E26) -> 0 | F27: =SUM(F24:F26) -> 82000000 | G27: =SUM(G24:G26) -> 40000000 | H27: =SUM(H24:H26) -> 105000000 | I27: =SUM(I24:I26) -> 40000000 | ... P27: =SUM(P24:P26) -> -15000000
A29: CASH RECONCILIATION
A30: NET CHANGE IN CASH | B30: =SUM(B17,B21,B27) -> 3901952 | C30: =SUM(C17,C21,C27) -> -3107589 | D30: =SUM(D17,D21,D27) -> 19141452 | E30: =SUM(E17,E21,E27) -> -6936828 | F30: =SUM(F17,F21,F27) -> 62200177 | G30: =SUM(G17,G21,G27) -> 1965754 | H30: =SUM(H17,H21,H27) -> 38888804 | I30: =SUM(I17,I21,I27) -> -55941688 | ... P30: =SUM(P17,P21,P27) -> -155219669
A31: Beginning cash and equivalents | B31: =0 -> 0 | C31: ='Balance Sheet'!B8 -> 3901952 | D31: ='Balance Sheet'!C8 -> 794363 | E31: ='Balance Sheet'!D8 -> 19935815 | F31: ='Balance Sheet'!E8 -> 12998987 | G31: ='Balance Sheet'!F8 -> 75199164 | H31: ='Balance Sheet'!G8 -> 77164918 | I31: ='Balance Sheet'!H8 -> 116053722 | J31: ='Balance Sheet'!I8 -> 60112034 | ... P31: ='Balance Sheet'!O8 -> -4125061
A32: ENDING CASH AND EQUIVALENTS | B32: =SUM(B30:B31) -> 3901952 | C32: =SUM(C30:C31) -> 794363 | D32: =SUM(D30:D31) -> 19935815 | E32: =SUM(E30:E31) -> 12998987 | F32: =SUM(F30:F31) -> 75199164 | G32: =SUM(G30:G31) -> 77164918 | H32: =SUM(H30:H31) -> 116053722 | I32: =SUM(I30:I31) -> 60112034 | ... P32: =SUM(P30:P31) -> -159344730
A33: Balance sheet ending cash (check) | B33: ='Balance Sheet'!B8 -> 3901952 | C33: ='Balance Sheet'!C8 -> 794363 | D33: ='Balance Sheet'!D8 -> 19935815 | E33: ='Balance Sheet'!E8 -> 12998987 | F33: ='Balance Sheet'!F8 -> 75199164 | G33: ='Balance Sheet'!G8 -> 77164918 | H33: ='Balance Sheet'!H8 -> 116053722 | I33: ='Balance Sheet'!I8 -> 60112034 | ... P33: ='Balance Sheet'!P8 -> -159344730
A34: Cash roll-forward difference (must = 0) | B34: =B32-B33 -> 0 | C34: =C32-C33 -> 0 | D34: =D32-D33 -> 0 | E34: =E32-E33 -> 0 | F34: =F32-F33 -> 0 | G34: =G32-G33 -> 0 | H34: =H32-H33 -> 0 | I34: =I32-I33 -> 0 | ... P34: =P32-P33 -> 0

Sheet Income Statement
A1: INCOME STATEMENT
A2: 2018–2025 synthetic history · 2026E (9 actual + 3 forecast) · 2027–2032 projections
A3: PERIOD | B3: 2018A | C3: 2019A | D3: 2020A | E3: 2021A | F3: 2022A | G3: 2023A | H3: 2024A | I3: 2025A | J3: 2026E (9A+3F) | K3: 2027F | L3: 2028F | M3: 2029F | N3: 2030F | O3: 2031F | P3: 2032F | Q3: Year | R3: Historical operating income ($) | S3: Forecast operating income ($) | T3: Operating break-even ($)
A4: FISCAL YEAR | B4: 2018 | C4: 2019 | D4: 2020 | E4: 2021 | F4: 2022 | G4: 2023 | H4: 2024 | I4: 2025 | J4: 2026 | K4: 2027 | L4: 2028 | M4: 2029 | N4: 2030 | O4: 2031 | P4: 2032 | Q4: =B4 -> 2018 | R4: =B29 -> -1920000 | S4: ="" | T4: 0
Q5: =C4 -> 2019 | R5: =C29 -> -2650000 | S5: ="" | T5: 0
A6: NET REVENUE | Q6: =D4 -> 2020 | R6: =D29 -> -4300000 | S6: ="" | T6: 0
A7: THX-101 licensed GLP-1 therapy | B7: =SUMIF('Monthly Data'!$B$2:$B1001,B$4,'Monthly Data'!$E$2:$E1001) -> 0 | C7: =SUMIF('Monthly Data'!$B$2:$B1001,C$4,'Monthly Data'!$E$2:$E1001) -> 0 | D7: =SUMIF('Monthly Data'!$B$2:$B1001,D$4,'Monthly Data'!$E$2:$E1001) -> 0 | E7: =SUMIF('Monthly Data'!$B$2:$B1001,E$4,'Monthly Data'!$E$2:$E1001) -> 0 | F7: =SUMIF('Monthly Data'!$B$2:$B1001,F$4,'Monthly Data'!$E$2:$E1001) -> 0 | G7: =SUMIF('Monthly Data'!$B$2:$B1001,G$4,'Monthly Data'!$E$2:$E1001) -> 0 | H7: =SUMIF('Monthly Data'!$B$2:$B1001,H$4,'Monthly Data'!$E$2:$E1001) -> 22000000 | I7: =SUMIF('Monthly Data'!$B$2:$B1001,I$4,'Monthly Data'!$E$2:$E1001) -> 65000000 | ... P7: =SUMIF('Monthly Data'!$B$2:$B1001,P$4,'Monthly Data'!$E$2:$E1001) -> 293464500 | Q7: =E4 -> 2021 | R7: =E29 -> -5682000 | S7: ="" | T7: 0
A8: THX-202 muscle treatment (scenario-dependent) | B8: =SUMIF('Monthly Data'!$B$2:$B1001,B$4,'Monthly Data'!$AI$2:$AI1001) -> 0 | C8: =SUMIF('Monthly Data'!$B$2:$B1001,C$4,'Monthly Data'!$AI$2:$AI1001) -> 0 | D8: =SUMIF('Monthly Data'!$B$2:$B1001,D$4,'Monthly Data'!$AI$2:$AI1001) -> 0 | E8: =SUMIF('Monthly Data'!$B$2:$B1001,E$4,'Monthly Data'!$AI$2:$AI1001) -> 0 | F8: =SUMIF('Monthly Data'!$B$2:$B1001,F$4,'Monthly Data'!$AI$2:$AI1001) -> 0 | G8: =SUMIF('Monthly Data'!$B$2:$B1001,G$4,'Monthly Data'!$AI$2:$AI1001) -> 0 | H8: =SUMIF('Monthly Data'!$B$2:$B1001,H$4,'Monthly Data'!$AI$2:$AI1001) -> 0 | I8: =SUMIF('Monthly Data'!$B$2:$B1001,I$4,'Monthly Data'!$AI$2:$AI1001) -> 0 | ... P8: =SUMIF('Monthly Data'!$B$2:$B1001,P$4,'Monthly Data'!$AI$2:$AI1001) -> 234454500 | Q8: =F4 -> 2022 | R8: =F29 -> -20150000 | S8: ="" | T8: 0
A9: Research services | B9: =SUMIF('Monthly Data'!$B$2:$B1001,B$4,'Monthly Data'!$F$2:$F1001) -> 0 | C9: =SUMIF('Monthly Data'!$B$2:$B1001,C$4,'Monthly Data'!$F$2:$F1001) -> 300000 | D9: =SUMIF('Monthly Data'!$B$2:$B1001,D$4,'Monthly Data'!$F$2:$F1001) -> 1000000 | E9: =SUMIF('Monthly Data'!$B$2:$B1001,E$4,'Monthly Data'!$F$2:$F1001) -> 2300000 | F9: =SUMIF('Monthly Data'!$B$2:$B1001,F$4,'Monthly Data'!$F$2:$F1001) -> 5000000 | G9: =SUMIF('Monthly Data'!$B$2:$B1001,G$4,'Monthly Data'!$F$2:$F1001) -> 11000000 | H9: =SUMIF('Monthly Data'!$B$2:$B1001,H$4,'Monthly Data'!$F$2:$F1001) -> 20000000 | I9: =SUMIF('Monthly Data'!$B$2:$B1001,I$4,'Monthly Data'!$F$2:$F1001) -> 22000000 | ... P9: =SUMIF('Monthly Data'!$B$2:$B1001,P$4,'Monthly Data'!$F$2:$F1001) -> 64616922 | Q9: =G4 -> 2023 | R9: =G29 -> -36430000 | S9: ="" | T9: 0
A10: Licensing / collaborations | B10: =SUMIF('Monthly Data'!$B$2:$B1001,B$4,'Monthly Data'!$G$2:$G1001) -> 0 | C10: =SUMIF('Monthly Data'!$B$2:$B1001,C$4,'Monthly Data'!$G$2:$G1001) -> 100000 | D10: =SUMIF('Monthly Data'!$B$2:$B1001,D$4,'Monthly Data'!$G$2:$G1001) -> 300000 | E10: =SUMIF('Monthly Data'!$B$2:$B1001,E$4,'Monthly Data'!$G$2:$G1001) -> 700000 | F10: =SUMIF('Monthly Data'!$B$2:$B1001,F$4,'Monthly Data'!$G$2:$G1001) -> 1000000 | G10: =SUMIF('Monthly Data'!$B$2:$B1001,G$4,'Monthly Data'!$G$2:$G1001) -> 6000000 | H10: =SUMIF('Monthly Data'!$B$2:$B1001,H$4,'Monthly Data'!$G$2:$G1001) -> 7000000 | I10: =SUMIF('Monthly Data'!$B$2:$B1001,I$4,'Monthly Data'!$G$2:$G1001) -> 7000000 | ... P10: =SUMIF('Monthly Data'!$B$2:$B1001,P$4,'Monthly Data'!$G$2:$G1001) -> 7000000 | Q10: =H4 -> 2024 | R10: =H29 -> -57380000 | S10: ="" | T10: 0
A11: TOTAL NET REVENUE | B11: =SUM(B7:B10) -> 0 | C11: =SUM(C7:C10) -> 400000 | D11: =SUM(D7:D10) -> 1300000 | E11: =SUM(E7:E10) -> 3000000 | F11: =SUM(F7:F10) -> 6000000 | G11: =SUM(G7:G10) -> 17000000 | H11: =SUM(H7:H10) -> 49000000 | I11: =SUM(I7:I10) -> 94000000 | ... P11: =SUM(P7:P10) -> 599535922 | Q11: =I4 -> 2025 | R11: =I29 -> -83520000 | S11: =I29 -> -83520000 | T11: 0
Q12: =J4 -> 2026 | R12: ="" | S12: =J29 -> -138167410 | T12: 0
A13: COST OF REVENUE | Q13: =K4 -> 2027 | R13: ="" | S13: =K29 -> -87732459 | T13: 0
A14: THX-101 manufacturing, royalty & distribution | B14: =SUMIF('Monthly Data'!$B$2:$B1001,B$4,'Monthly Data'!$H$2:$H1001)+SUMIF('Monthly Data'!$B$2:$B1001,B$4,'Monthly Data'!$I$2:$I1001) -> 0 | C14: =SUMIF('Monthly Data'!$B$2:$B1001,C$4,'Monthly Data'!$H$2:$H1001)+SUMIF('Monthly Data'!$B$2:$B1001,C$4,'Monthly Data'!$I$2:$I1001) -> 0 | D14: =SUMIF('Monthly Data'!$B$2:$B1001,D$4,'Monthly Data'!$H$2:$H1001)+SUMIF('Monthly Data'!$B$2:$B1001,D$4,'Monthly Data'!$I$2:$I1001) -> 0 | E14: =SUMIF('Monthly Data'!$B$2:$B1001,E$4,'Monthly Data'!$H$2:$H1001)+SUMIF('Monthly Data'!$B$2:$B1001,E$4,'Monthly Data'!$I$2:$I1001) -> 0 | F14: =SUMIF('Monthly Data'!$B$2:$B1001,F$4,'Monthly Data'!$H$2:$H1001)+SUMIF('Monthly Data'!$B$2:$B1001,F$4,'Monthly Data'!$I$2:$I1001) -> 0 | G14: =SUMIF('Monthly Data'!$B$2:$B1001,G$4,'Monthly Data'!$H$2:$H1001)+SUMIF('Monthly Data'!$B$2:$B1001,G$4,'Monthly Data'!$I$2:$I1001) -> 0 | H14: =SUMIF('Monthly Data'!$B$2:$B1001,H$4,'Monthly Data'!$H$2:$H1001)+SUMIF('Monthly Data'!$B$2:$B1001,H$4,'Monthly Data'!$I$2:$I1001) -> 6820000 | I14: =SUMIF('Monthly Data'!$B$2:$B1001,I$4,'Monthly Data'!$H$2:$H1001)+SUMIF('Monthly Data'!$B$2:$B1001,I$4,'Monthly Data'!$I$2:$I1001) -> 19500000 | ... P14: =SUMIF('Monthly Data'!$B$2:$B1001,P$4,'Monthly Data'!$H$2:$H1001)+SUMIF('Monthly Data'!$B$2:$B1001,P$4,'Monthly Data'!$I$2:$I1001) -> 80409545 | Q14: =L4 -> 2028 | R14: ="" | S14: =L29 -> -43855319 | T14: 0
A15: THX-202 manufacturing & distribution | B15: =SUMIF('Monthly Data'!$B$2:$B1001,B$4,'Monthly Data'!$AJ$2:$AJ1001) -> 0 | C15: =SUMIF('Monthly Data'!$B$2:$B1001,C$4,'Monthly Data'!$AJ$2:$AJ1001) -> 0 | D15: =SUMIF('Monthly Data'!$B$2:$B1001,D$4,'Monthly Data'!$AJ$2:$AJ1001) -> 0 | E15: =SUMIF('Monthly Data'!$B$2:$B1001,E$4,'Monthly Data'!$AJ$2:$AJ1001) -> 0 | F15: =SUMIF('Monthly Data'!$B$2:$B1001,F$4,'Monthly Data'!$AJ$2:$AJ1001) -> 0 | G15: =SUMIF('Monthly Data'!$B$2:$B1001,G$4,'Monthly Data'!$AJ$2:$AJ1001) -> 0 | H15: =SUMIF('Monthly Data'!$B$2:$B1001,H$4,'Monthly Data'!$AJ$2:$AJ1001) -> 0 | I15: =SUMIF('Monthly Data'!$B$2:$B1001,I$4,'Monthly Data'!$AJ$2:$AJ1001) -> 0 | ... P15: =SUMIF('Monthly Data'!$B$2:$B1001,P$4,'Monthly Data'!$AJ$2:$AJ1001) -> 78575900 | Q15: =M4 -> 2029 | R15: ="" | S15: =M29 -> -47073355 | T15: 0
A16: Research service delivery | B16: =SUMIF('Monthly Data'!$B$2:$B1001,B$4,'Monthly Data'!$J$2:$J1001) -> 0 | C16: =SUMIF('Monthly Data'!$B$2:$B1001,C$4,'Monthly Data'!$J$2:$J1001) -> 120000 | D16: =SUMIF('Monthly Data'!$B$2:$B1001,D$4,'Monthly Data'!$J$2:$J1001) -> 440000 | E16: =SUMIF('Monthly Data'!$B$2:$B1001,E$4,'Monthly Data'!$J$2:$J1001) -> 1012000 | F16: =SUMIF('Monthly Data'!$B$2:$B1001,F$4,'Monthly Data'!$J$2:$J1001) -> 2200000 | G16: =SUMIF('Monthly Data'!$B$2:$B1001,G$4,'Monthly Data'!$J$2:$J1001) -> 4950000 | H16: =SUMIF('Monthly Data'!$B$2:$B1001,H$4,'Monthly Data'!$J$2:$J1001) -> 9000000 | I16: =SUMIF('Monthly Data'!$B$2:$B1001,I$4,'Monthly Data'!$J$2:$J1001) -> 9460000 | ... P16: =SUMIF('Monthly Data'!$B$2:$B1001,P$4,'Monthly Data'!$J$2:$J1001) -> 28442804 | Q16: =N4 -> 2030 | R16: ="" | S16: =N29 -> -56815353
A17: Licensing delivery | B17: =SUMIF('Monthly Data'!$B$2:$B1001,B$4,'Monthly Data'!$K$2:$K1001) -> 0 | C17: =SUMIF('Monthly Data'!$B$2:$B1001,C$4,'Monthly Data'!$K$2:$K1001) -> 10000 | D17: =SUMIF('Monthly Data'!$B$2:$B1001,D$4,'Monthly Data'!$K$2:$K1001) -> 30000 | E17: =SUMIF('Monthly Data'!$B$2:$B1001,E$4,'Monthly Data'!$K$2:$K1001) -> 70000 | F17: =SUMIF('Monthly Data'!$B$2:$B1001,F$4,'Monthly Data'!$K$2:$K1001) -> 100000 | G17: =SUMIF('Monthly Data'!$B$2:$B1001,G$4,'Monthly Data'!$K$2:$K1001) -> 480000 | H17: =SUMIF('Monthly Data'!$B$2:$B1001,H$4,'Monthly Data'!$K$2:$K1001) -> 560000 | I17: =SUMIF('Monthly Data'!$B$2:$B1001,I$4,'Monthly Data'!$K$2:$K1001) -> 560000 | ... P17: =SUMIF('Monthly Data'!$B$2:$B1001,P$4,'Monthly Data'!$K$2:$K1001) -> 560003 | Q17: =O4 -> 2031 | R17: ="" | S17: =O29 -> -74480551
A18: TOTAL COST OF REVENUE | B18: =SUM(B14:B17) -> 0 | C18: =SUM(C14:C17) -> 130000 | D18: =SUM(D14:D17) -> 470000 | E18: =SUM(E14:E17) -> 1082000 | F18: =SUM(F14:F17) -> 2300000 | G18: =SUM(G14:G17) -> 5430000 | H18: =SUM(H14:H17) -> 16380000 | I18: =SUM(I14:I17) -> 29520000 | ... P18: =SUM(P14:P17) -> 187988252 | Q18: =P4 -> 2032 | R18: ="" | S18: =P29 -> -102364853
A19: GROSS PROFIT | B19: =B11-B18 -> 0 | C19: =C11-C18 -> 270000 | D19: =D11-D18 -> 830000 | E19: =E11-E18 -> 1918000 | F19: =F11-F18 -> 3700000 | G19: =G11-G18 -> 11570000 | H19: =H11-H18 -> 32620000 | I19: =I11-I18 -> 64480000 | ... P19: =P11-P18 -> 411547670
A20: Gross margin % | B20: =IFERROR(B19/B11,0) -> 0 | C20: =IFERROR(C19/C11,0) -> 0.675 | D20: =IFERROR(D19/D11,0) -> 0.63846154 | E20: =IFERROR(E19/E11,0) -> 0.63933333 | F20: =IFERROR(F19/F11,0) -> 0.61666667 | G20: =IFERROR(G19/G11,0) -> 0.68058824 | H20: =IFERROR(H19/H11,0) -> 0.66571429 | I20: =IFERROR(I19/I11,0) -> 0.68595745 | ... P20: =IFERROR(P19/P11,0) -> 0.68644372
A22: OPERATING EXPENSES
A23: Research & development | B23: =SUMIF('Monthly Data'!$B$2:$B1001,B$4,'Monthly Data'!$L$2:$L1001)+SUMIF('Monthly Data'!$B$2:$B1001,B$4,'Monthly Data'!$M$2:$M1001) -> 1150000 | C23: =SUMIF('Monthly Data'!$B$2:$B1001,C$4,'Monthly Data'!$L$2:$L1001)+SUMIF('Monthly Data'!$B$2:$B1001,C$4,'Monthly Data'!$M$2:$M1001) -> 1650000 | D23: =SUMIF('Monthly Data'!$B$2:$B1001,D$4,'Monthly Data'!$L$2:$L1001)+SUMIF('Monthly Data'!$B$2:$B1001,D$4,'Monthly Data'!$M$2:$M1001) -> 2750000 | E23: =SUMIF('Monthly Data'!$B$2:$B1001,E$4,'Monthly Data'!$L$2:$L1001)+SUMIF('Monthly Data'!$B$2:$B1001,E$4,'Monthly Data'!$M$2:$M1001) -> 3800000 | F23: =SUMIF('Monthly Data'!$B$2:$B1001,F$4,'Monthly Data'!$L$2:$L1001)+SUMIF('Monthly Data'!$B$2:$B1001,F$4,'Monthly Data'!$M$2:$M1001) -> 15000000 | G23: =SUMIF('Monthly Data'!$B$2:$B1001,G$4,'Monthly Data'!$L$2:$L1001)+SUMIF('Monthly Data'!$B$2:$B1001,G$4,'Monthly Data'!$M$2:$M1001) -> 22000000 | H23: =SUMIF('Monthly Data'!$B$2:$B1001,H$4,'Monthly Data'!$L$2:$L1001)+SUMIF('Monthly Data'!$B$2:$B1001,H$4,'Monthly Data'!$M$2:$M1001) -> 44000000 | I23: =SUMIF('Monthly Data'!$B$2:$B1001,I$4,'Monthly Data'!$L$2:$L1001)+SUMIF('Monthly Data'!$B$2:$B1001,I$4,'Monthly Data'!$M$2:$M1001) -> 70000000 | ... P23: =SUMIF('Monthly Data'!$B$2:$B1001,P$4,'Monthly Data'!$L$2:$L1001)+SUMIF('Monthly Data'!$B$2:$B1001,P$4,'Monthly Data'!$M$2:$M1001) -> 149600421
A24: Sales and marketing | B24: =SUMIF('Monthly Data'!$B$2:$B1001,B$4,'Monthly Data'!$N$2:$N1001) -> 100000 | C24: =SUMIF('Monthly Data'!$B$2:$B1001,C$4,'Monthly Data'!$N$2:$N1001) -> 200000 | D24: =SUMIF('Monthly Data'!$B$2:$B1001,D$4,'Monthly Data'!$N$2:$N1001) -> 400000 | E24: =SUMIF('Monthly Data'!$B$2:$B1001,E$4,'Monthly Data'!$N$2:$N1001) -> 650000 | F24: =SUMIF('Monthly Data'!$B$2:$B1001,F$4,'Monthly Data'!$N$2:$N1001) -> 2000000 | G24: =SUMIF('Monthly Data'!$B$2:$B1001,G$4,'Monthly Data'!$N$2:$N1001) -> 9000000 | H24: =SUMIF('Monthly Data'!$B$2:$B1001,H$4,'Monthly Data'!$N$2:$N1001) -> 18000000 | I24: =SUMIF('Monthly Data'!$B$2:$B1001,I$4,'Monthly Data'!$N$2:$N1001) -> 36000000 | ... P24: =SUMIF('Monthly Data'!$B$2:$B1001,P$4,'Monthly Data'!$N$2:$N1001) -> 202242301
A25: General and administration | B25: =SUMIF('Monthly Data'!$B$2:$B1001,B$4,'Monthly Data'!$O$2:$O1001) -> 600000 | C25: =SUMIF('Monthly Data'!$B$2:$B1001,C$4,'Monthly Data'!$O$2:$O1001) -> 850000 | D25: =SUMIF('Monthly Data'!$B$2:$B1001,D$4,'Monthly Data'!$O$2:$O1001) -> 1500000 | E25: =SUMIF('Monthly Data'!$B$2:$B1001,E$4,'Monthly Data'!$O$2:$O1001) -> 2250000 | F25: =SUMIF('Monthly Data'!$B$2:$B1001,F$4,'Monthly Data'!$O$2:$O1001) -> 5000000 | G25: =SUMIF('Monthly Data'!$B$2:$B1001,G$4,'Monthly Data'!$O$2:$O1001) -> 12000000 | H25: =SUMIF('Monthly Data'!$B$2:$B1001,H$4,'Monthly Data'!$O$2:$O1001) -> 19000000 | I25: =SUMIF('Monthly Data'!$B$2:$B1001,I$4,'Monthly Data'!$O$2:$O1001) -> 28000000 | ... P25: =SUMIF('Monthly Data'!$B$2:$B1001,P$4,'Monthly Data'!$O$2:$O1001) -> 70337497
A26: Noncash stock compensation | B26: =SUMIF('Monthly Data'!$B$2:$B1001,B$4,'Monthly Data'!$P$2:$P1001) -> 40000 | C26: =SUMIF('Monthly Data'!$B$2:$B1001,C$4,'Monthly Data'!$P$2:$P1001) -> 100000 | D26: =SUMIF('Monthly Data'!$B$2:$B1001,D$4,'Monthly Data'!$P$2:$P1001) -> 240000 | E26: =SUMIF('Monthly Data'!$B$2:$B1001,E$4,'Monthly Data'!$P$2:$P1001) -> 450000 | F26: =SUMIF('Monthly Data'!$B$2:$B1001,F$4,'Monthly Data'!$P$2:$P1001) -> 750000 | G26: =SUMIF('Monthly Data'!$B$2:$B1001,G$4,'Monthly Data'!$P$2:$P1001) -> 2000000 | H26: =SUMIF('Monthly Data'!$B$2:$B1001,H$4,'Monthly Data'!$P$2:$P1001) -> 4000000 | I26: =SUMIF('Monthly Data'!$B$2:$B1001,I$4,'Monthly Data'!$P$2:$P1001) -> 7000000 | ... P26: =SUMIF('Monthly Data'!$B$2:$B1001,P$4,'Monthly Data'!$P$2:$P1001) -> 36669490
A27: Depreciation and amortization | B27: =SUMIF('Monthly Data'!$B$2:$B1001,B$4,'Monthly Data'!$Q$2:$Q1001) -> 30000 | C27: =SUMIF('Monthly Data'!$B$2:$B1001,C$4,'Monthly Data'!$Q$2:$Q1001) -> 120000 | D27: =SUMIF('Monthly Data'!$B$2:$B1001,D$4,'Monthly Data'!$Q$2:$Q1001) -> 240000 | E27: =SUMIF('Monthly Data'!$B$2:$B1001,E$4,'Monthly Data'!$Q$2:$Q1001) -> 450000 | F27: =SUMIF('Monthly Data'!$B$2:$B1001,F$4,'Monthly Data'!$Q$2:$Q1001) -> 1100000 | G27: =SUMIF('Monthly Data'!$B$2:$B1001,G$4,'Monthly Data'!$Q$2:$Q1001) -> 3000000 | H27: =SUMIF('Monthly Data'!$B$2:$B1001,H$4,'Monthly Data'!$Q$2:$Q1001) -> 5000000 | I27: =SUMIF('Monthly Data'!$B$2:$B1001,I$4,'Monthly Data'!$Q$2:$Q1001) -> 7000000 | ... P27: =SUMIF('Monthly Data'!$B$2:$B1001,P$4,'Monthly Data'!$Q$2:$Q1001) -> 55062814
A28: TOTAL OPERATING EXPENSES | B28: =SUM(B23:B27) -> 1920000 | C28: =SUM(C23:C27) -> 2920000 | D28: =SUM(D23:D27) -> 5130000 | E28: =SUM(E23:E27) -> 7600000 | F28: =SUM(F23:F27) -> 23850000 | G28: =SUM(G23:G27) -> 48000000 | H28: =SUM(H23:H27) -> 90000000 | I28: =SUM(I23:I27) -> 148000000 | ... P28: =SUM(P23:P27) -> 513912523
A29: OPERATING INCOME / (LOSS) | B29: =B19-B28 -> -1920000 | C29: =C19-C28 -> -2650000 | D29: =D19-D28 -> -4300000 | E29: =E19-E28 -> -5682000 | F29: =F19-F28 -> -20150000 | G29: =G19-G28 -> -36430000 | H29: =H19-H28 -> -57380000 | I29: =I19-I28 -> -83520000 | ... P29: =P19-P28 -> -102364853
A30: Operating margin % | B30: =IFERROR(B29/B11,0) -> 0 | C30: =IFERROR(C29/C11,0) -> -6.625 | D30: =IFERROR(D29/D11,0) -> -3.3076923 | E30: =IFERROR(E29/E11,0) -> -1.894 | F30: =IFERROR(F29/F11,0) -> -3.3583333 | G30: =IFERROR(G29/G11,0) -> -2.1429412 | H30: =IFERROR(H29/H11,0) -> -1.1710204 | I30: =IFERROR(I29/I11,0) -> -0.88851064 | ... P30: =IFERROR(P29/P11,0) -> -0.17074015
A32: OTHER ITEMS
A33: Interest expense (venture debt) | B33: =SUMIF('Monthly Data'!$B$2:$B1001,B$4,'Monthly Data'!$R$2:$R1001) -> 0 | C33: =SUMIF('Monthly Data'!$B$2:$B1001,C$4,'Monthly Data'!$R$2:$R1001) -> 0 | D33: =SUMIF('Monthly Data'!$B$2:$B1001,D$4,'Monthly Data'!$R$2:$R1001) -> 0 | E33: =SUMIF('Monthly Data'!$B$2:$B1001,E$4,'Monthly Data'!$R$2:$R1001) -> 0 | F33: =SUMIF('Monthly Data'!$B$2:$B1001,F$4,'Monthly Data'!$R$2:$R1001) -> 935000 | G33: =SUMIF('Monthly Data'!$B$2:$B1001,G$4,'Monthly Data'!$R$2:$R1001) -> 3570000 | H33: =SUMIF('Monthly Data'!$B$2:$B1001,H$4,'Monthly Data'!$R$2:$R1001) -> 5057500 | I33: =SUMIF('Monthly Data'!$B$2:$B1001,I$4,'Monthly Data'!$R$2:$R1001) -> 6545000 | ... P33: =SUMIF('Monthly Data'!$B$2:$B1001,P$4,'Monthly Data'!$R$2:$R1001) -> 1763746
A34: INCOME / (LOSS) BEFORE TAX | B34: =B29-B33 -> -1920000 | C34: =C29-C33 -> -2650000 | D34: =D29-D33 -> -4300000 | E34: =E29-E33 -> -5682000 | F34: =F29-F33 -> -21085000 | G34: =G29-G33 -> -40000000 | H34: =H29-H33 -> -62437500 | I34: =I29-I33 -> -90065000 | ... P34: =P29-P33 -> -104128599
A35: Income taxes | B35: =SUMIF('Monthly Data'!$B$2:$B1001,B$4,'Monthly Data'!$S$2:$S1001) -> 0 | C35: =SUMIF('Monthly Data'!$B$2:$B1001,C$4,'Monthly Data'!$S$2:$S1001) -> 0 | D35: =SUMIF('Monthly Data'!$B$2:$B1001,D$4,'Monthly Data'!$S$2:$S1001) -> 0 | E35: =SUMIF('Monthly Data'!$B$2:$B1001,E$4,'Monthly Data'!$S$2:$S1001) -> 0 | F35: =SUMIF('Monthly Data'!$B$2:$B1001,F$4,'Monthly Data'!$S$2:$S1001) -> 0 | G35: =SUMIF('Monthly Data'!$B$2:$B1001,G$4,'Monthly Data'!$S$2:$S1001) -> 0 | H35: =SUMIF('Monthly Data'!$B$2:$B1001,H$4,'Monthly Data'!$S$2:$S1001) -> 0 | I35: =SUMIF('Monthly Data'!$B$2:$B1001,I$4,'Monthly Data'!$S$2:$S1001) -> 0 | ... P35: =SUMIF('Monthly Data'!$B$2:$B1001,P$4,'Monthly Data'!$S$2:$S1001) -> 0
A36: NET INCOME / (LOSS) | B36: =B34-B35 -> -1920000 | C36: =C34-C35 -> -2650000 | D36: =D34-D35 -> -4300000 | E36: =E34-E35 -> -5682000 | F36: =F34-F35 -> -21085000 | G36: =G34-G35 -> -40000000 | H36: =H34-H35 -> -62437500 | I36: =I34-I35 -> -90065000 | ... P36: =P34-P35 -> -104128599
A37: Net margin % | B37: =IFERROR(B36/B11,0) -> 0 | C37: =IFERROR(C36/C11,0) -> -6.625 | D37: =IFERROR(D36/D11,0) -> -3.3076923 | E37: =IFERROR(E36/E11,0) -> -1.894 | F37: =IFERROR(F36/F11,0) -> -3.5141667 | G37: =IFERROR(G36/G11,0) -> -2.3529412 | H37: =IFERROR(H36/H11,0) -> -1.2742347 | I37: =IFERROR(I36/I11,0) -> -0.9581383 | ... P37: =IFERROR(P36/P11,0) -> -0.173682
A38: R&D / total revenue | B38: =IFERROR(B23/B11,0) -> 0 | C38: =IFERROR(C23/C11,0) -> 4.125 | D38: =IFERROR(D23/D11,0) -> 2.1153846 | E38: =IFERROR(E23/E11,0) -> 1.2666667 | F38: =IFERROR(F23/F11,0) -> 2.5 | G38: =IFERROR(G23/G11,0) -> 1.2941176 | H38: =IFERROR(H23/H11,0) -> 0.89795918 | I38: =IFERROR(I23/I11,0) -> 0.74468085 | ... P38: =IFERROR(P23/P11,0) -> 0.24952704

Sheet Balance Sheet
A1: BALANCE SHEET
A2: 2018–2025 history · 2026–2032 forecasts
A4: PERIOD | B4: 2018A | C4: 2019A | D4: 2020A | E4: 2021A | F4: 2022A | G4: 2023A | H4: 2024A | I4: 2025A | J4: 2026E (9A+3F) | K4: 2027F | L4: 2028F | M4: 2029F | N4: 2030F | O4: 2031F | P4: 2032F
A5: FISCAL YEAR | B5: 2018 | C5: 2019 | D5: 2020 | E5: 2021 | F5: 2022 | G5: 2023 | H5: 2024 | I5: 2025 | J5: 2026 | K5: 2027 | L5: 2028 | M5: 2029 | N5: 2030 | O5: 2031 | P5: 2032
A7: ASSETS
A8: Cash and cash equivalents | B8: {=INDEX('Monthly Data'!$AF$2:$AF1001,MATCH(DATE(B$5,12,1),'Monthly Data'!$A$2:$A1001,0))} -> 3901952 | C8: {=INDEX('Monthly Data'!$AF$2:$AF1001,MATCH(DATE(C$5,12,1),'Monthly Data'!$A$2:$A1001,0))} -> 794363 | D8: {=INDEX('Monthly Data'!$AF$2:$AF1001,MATCH(DATE(D$5,12,1),'Monthly Data'!$A$2:$A1001,0))} -> 19935815 | E8: {=INDEX('Monthly Data'!$AF$2:$AF1001,MATCH(DATE(E$5,12,1),'Monthly Data'!$A$2:$A1001,0))} -> 12998987 | F8: {=INDEX('Monthly Data'!$AF$2:$AF1001,MATCH(DATE(F$5,12,1),'Monthly Data'!$A$2:$A1001,0))} -> 75199164 | G8: {=INDEX('Monthly Data'!$AF$2:$AF1001,MATCH(DATE(G$5,12,1),'Monthly Data'!$A$2:$A1001,0))} -> 77164918 | H8: {=INDEX('Monthly Data'!$AF$2:$AF1001,MATCH(DATE(H$5,12,1),'Monthly Data'!$A$2:$A1001,0))} -> 116053722 | I8: {=INDEX('Monthly Data'!$AF$2:$AF1001,MATCH(DATE(I$5,12,1),'Monthly Data'!$A$2:$A1001,0))} -> 60112034 | ... P8: {=INDEX('Monthly Data'!$AF$2:$AF1001,MATCH(DATE(P$5,12,1),'Monthly Data'!$A$2:$A1001,0))} -> -159344730
A9: Accounts receivable | B9: {=INDEX('Monthly Data'!$X$2:$X1001,MATCH(DATE(B$5,12,1),'Monthly Data'!$A$2:$A1001,0))} -> 0 | C9: {=INDEX('Monthly Data'!$X$2:$X1001,MATCH(DATE(C$5,12,1),'Monthly Data'!$A$2:$A1001,0))} -> 43836 | D9: {=INDEX('Monthly Data'!$X$2:$X1001,MATCH(DATE(D$5,12,1),'Monthly Data'!$A$2:$A1001,0))} -> 142466 | E9: {=INDEX('Monthly Data'!$X$2:$X1001,MATCH(DATE(E$5,12,1),'Monthly Data'!$A$2:$A1001,0))} -> 345205 | F9: {=INDEX('Monthly Data'!$X$2:$X1001,MATCH(DATE(F$5,12,1),'Monthly Data'!$A$2:$A1001,0))} -> 739726 | G9: {=INDEX('Monthly Data'!$X$2:$X1001,MATCH(DATE(G$5,12,1),'Monthly Data'!$A$2:$A1001,0))} -> 2235616 | H9: {=INDEX('Monthly Data'!$X$2:$X1001,MATCH(DATE(H$5,12,1),'Monthly Data'!$A$2:$A1001,0))} -> 6980822 | I9: {=INDEX('Monthly Data'!$X$2:$X1001,MATCH(DATE(I$5,12,1),'Monthly Data'!$A$2:$A1001,0))} -> 14421918 | ... P9: {=INDEX('Monthly Data'!$X$2:$X1001,MATCH(DATE(P$5,12,1),'Monthly Data'!$A$2:$A1001,0))} -> 73140999
A10: Inventory | B10: {=INDEX('Monthly Data'!$Y$2:$Y1001,MATCH(DATE(B$5,12,1),'Monthly Data'!$A$2:$A1001,0))} -> 0 | C10: {=INDEX('Monthly Data'!$Y$2:$Y1001,MATCH(DATE(C$5,12,1),'Monthly Data'!$A$2:$A1001,0))} -> 0 | D10: {=INDEX('Monthly Data'!$Y$2:$Y1001,MATCH(DATE(D$5,12,1),'Monthly Data'!$A$2:$A1001,0))} -> 0 | E10: {=INDEX('Monthly Data'!$Y$2:$Y1001,MATCH(DATE(E$5,12,1),'Monthly Data'!$A$2:$A1001,0))} -> 0 | F10: {=INDEX('Monthly Data'!$Y$2:$Y1001,MATCH(DATE(F$5,12,1),'Monthly Data'!$A$2:$A1001,0))} -> 0 | G10: {=INDEX('Monthly Data'!$Y$2:$Y1001,MATCH(DATE(G$5,12,1),'Monthly Data'!$A$2:$A1001,0))} -> 0 | H10: {=INDEX('Monthly Data'!$Y$2:$Y1001,MATCH(DATE(H$5,12,1),'Monthly Data'!$A$2:$A1001,0))} -> 2591600 | I10: {=INDEX('Monthly Data'!$Y$2:$Y1001,MATCH(DATE(I$5,12,1),'Monthly Data'!$A$2:$A1001,0))} -> 6240000 | ... P10: {=INDEX('Monthly Data'!$Y$2:$Y1001,MATCH(DATE(P$5,12,1),'Monthly Data'!$A$2:$A1001,0))} -> 41577135
A11: Prepaid expenses | B11: {=INDEX('Monthly Data'!$Z$2:$Z1001,MATCH(DATE(B$5,12,1),'Monthly Data'!$A$2:$A1001,0))} -> 0 | C11: {=INDEX('Monthly Data'!$Z$2:$Z1001,MATCH(DATE(C$5,12,1),'Monthly Data'!$A$2:$A1001,0))} -> 20000 | D11: {=INDEX('Monthly Data'!$Z$2:$Z1001,MATCH(DATE(D$5,12,1),'Monthly Data'!$A$2:$A1001,0))} -> 65000 | E11: {=INDEX('Monthly Data'!$Z$2:$Z1001,MATCH(DATE(E$5,12,1),'Monthly Data'!$A$2:$A1001,0))} -> 150000 | F11: {=INDEX('Monthly Data'!$Z$2:$Z1001,MATCH(DATE(F$5,12,1),'Monthly Data'!$A$2:$A1001,0))} -> 360000 | G11: {=INDEX('Monthly Data'!$Z$2:$Z1001,MATCH(DATE(G$5,12,1),'Monthly Data'!$A$2:$A1001,0))} -> 1020000 | H11: {=INDEX('Monthly Data'!$Z$2:$Z1001,MATCH(DATE(H$5,12,1),'Monthly Data'!$A$2:$A1001,0))} -> 2940000 | I11: {=INDEX('Monthly Data'!$Z$2:$Z1001,MATCH(DATE(I$5,12,1),'Monthly Data'!$A$2:$A1001,0))} -> 5640000 | ... P11: {=INDEX('Monthly Data'!$Z$2:$Z1001,MATCH(DATE(P$5,12,1),'Monthly Data'!$A$2:$A1001,0))} -> 17039082
A12: Property, plant and equipment (net) | B12: =0-'Cash Flow'!B20-'Income Statement'!B27 -> 320000 | C12: ='Balance Sheet'!B12-'Cash Flow'!C20-'Income Statement'!C27 -> 950000 | D12: ='Balance Sheet'!C12-'Cash Flow'!D20-'Income Statement'!D27 -> 1960000 | E12: ='Balance Sheet'!D12-'Cash Flow'!E20-'Income Statement'!E27 -> 4010000 | F12: ='Balance Sheet'!E12-'Cash Flow'!F20-'Income Statement'!F27 -> 5910000 | G12: ='Balance Sheet'!F12-'Cash Flow'!G20-'Income Statement'!G27 -> 8910000 | H12: ='Balance Sheet'!G12-'Cash Flow'!H20-'Income Statement'!H27 -> 15910000 | I12: ='Balance Sheet'!H12-'Cash Flow'!I20-'Income Statement'!I27 -> 24910000 | J12: ='Balance Sheet'!I12-'Cash Flow'!J20-'Income Statement'!J27 -> 36517249 | ... P12: ='Balance Sheet'!O12-'Cash Flow'!P20-'Income Statement'!P27 -> 250956802
A13: TOTAL CURRENT ASSETS | B13: =SUM(B8:B11) -> 3901952 | C13: =SUM(C8:C11) -> 858199 | D13: =SUM(D8:D11) -> 20143281 | E13: =SUM(E8:E11) -> 13494192 | F13: =SUM(F8:F11) -> 76298890 | G13: =SUM(G8:G11) -> 80420534 | H13: =SUM(H8:H11) -> 128566144 | I13: =SUM(I8:I11) -> 86413952 | ... P13: =SUM(P8:P11) -> -27587514
A14: TOTAL ASSETS | B14: =SUM(B12:B13) -> 4221952 | C14: =SUM(C12:C13) -> 1808199 | D14: =SUM(D12:D13) -> 22103281 | E14: =SUM(E12:E13) -> 17504192 | F14: =SUM(F12:F13) -> 82208890 | G14: =SUM(G12:G13) -> 89330534 | H14: =SUM(H12:H13) -> 144476144 | I14: =SUM(I12:I13) -> 111323952 | ... P14: =SUM(P12:P13) -> 223369288
A16: LIABILITIES
A17: Accounts payable | B17: {=INDEX('Monthly Data'!$AA$2:$AA1001,MATCH(DATE(B$5,12,1),'Monthly Data'!$A$2:$A1001,0))} -> 9452 | C17: {=INDEX('Monthly Data'!$AA$2:$AA1001,MATCH(DATE(C$5,12,1),'Monthly Data'!$A$2:$A1001,0))} -> 36199 | D17: {=INDEX('Monthly Data'!$AA$2:$AA1001,MATCH(DATE(D$5,12,1),'Monthly Data'!$A$2:$A1001,0))} -> 111781 | E17: {=INDEX('Monthly Data'!$AA$2:$AA1001,MATCH(DATE(E$5,12,1),'Monthly Data'!$A$2:$A1001,0))} -> 210192 | F17: {=INDEX('Monthly Data'!$AA$2:$AA1001,MATCH(DATE(F$5,12,1),'Monthly Data'!$A$2:$A1001,0))} -> 745890 | G17: {=INDEX('Monthly Data'!$AA$2:$AA1001,MATCH(DATE(G$5,12,1),'Monthly Data'!$A$2:$A1001,0))} -> 1347534 | H17: {=INDEX('Monthly Data'!$AA$2:$AA1001,MATCH(DATE(H$5,12,1),'Monthly Data'!$A$2:$A1001,0))} -> 3525644 | I17: {=INDEX('Monthly Data'!$AA$2:$AA1001,MATCH(DATE(I$5,12,1),'Monthly Data'!$A$2:$A1001,0))} -> 6183452 | ... P17: {=INDEX('Monthly Data'!$AA$2:$AA1001,MATCH(DATE(P$5,12,1),'Monthly Data'!$A$2:$A1001,0))} -> 26082819
A18: Accrued operating expenses | B18: {=INDEX('Monthly Data'!$AB$2:$AB1001,MATCH(DATE(B$5,12,1),'Monthly Data'!$A$2:$A1001,0))} -> 92500 | C18: {=INDEX('Monthly Data'!$AB$2:$AB1001,MATCH(DATE(C$5,12,1),'Monthly Data'!$A$2:$A1001,0))} -> 162000 | D18: {=INDEX('Monthly Data'!$AB$2:$AB1001,MATCH(DATE(D$5,12,1),'Monthly Data'!$A$2:$A1001,0))} -> 325500 | E18: {=INDEX('Monthly Data'!$AB$2:$AB1001,MATCH(DATE(E$5,12,1),'Monthly Data'!$A$2:$A1001,0))} -> 536000 | F18: {=INDEX('Monthly Data'!$AB$2:$AB1001,MATCH(DATE(F$5,12,1),'Monthly Data'!$A$2:$A1001,0))} -> 2200000 | G18: {=INDEX('Monthly Data'!$AB$2:$AB1001,MATCH(DATE(G$5,12,1),'Monthly Data'!$A$2:$A1001,0))} -> 4300000 | H18: {=INDEX('Monthly Data'!$AB$2:$AB1001,MATCH(DATE(H$5,12,1),'Monthly Data'!$A$2:$A1001,0))} -> 8505000 | I18: {=INDEX('Monthly Data'!$AB$2:$AB1001,MATCH(DATE(I$5,12,1),'Monthly Data'!$A$2:$A1001,0))} -> 14740000 | ... P18: {=INDEX('Monthly Data'!$AB$2:$AB1001,MATCH(DATE(P$5,12,1),'Monthly Data'!$A$2:$A1001,0))} -> 40411198
A19: Deferred contract revenue | B19: {=INDEX('Monthly Data'!$AC$2:$AC1001,MATCH(DATE(B$5,12,1),'Monthly Data'!$A$2:$A1001,0))} -> 0 | C19: {=INDEX('Monthly Data'!$AC$2:$AC1001,MATCH(DATE(C$5,12,1),'Monthly Data'!$A$2:$A1001,0))} -> 40000 | D19: {=INDEX('Monthly Data'!$AC$2:$AC1001,MATCH(DATE(D$5,12,1),'Monthly Data'!$A$2:$A1001,0))} -> 156000 | E19: {=INDEX('Monthly Data'!$AC$2:$AC1001,MATCH(DATE(E$5,12,1),'Monthly Data'!$A$2:$A1001,0))} -> 480000 | F19: {=INDEX('Monthly Data'!$AC$2:$AC1001,MATCH(DATE(F$5,12,1),'Monthly Data'!$A$2:$A1001,0))} -> 1320000 | G19: {=INDEX('Monthly Data'!$AC$2:$AC1001,MATCH(DATE(G$5,12,1),'Monthly Data'!$A$2:$A1001,0))} -> 3740000 | H19: {=INDEX('Monthly Data'!$AC$2:$AC1001,MATCH(DATE(H$5,12,1),'Monthly Data'!$A$2:$A1001,0))} -> 5940000 | I19: {=INDEX('Monthly Data'!$AC$2:$AC1001,MATCH(DATE(I$5,12,1),'Monthly Data'!$A$2:$A1001,0))} -> 6960000 | ... P19: {=INDEX('Monthly Data'!$AC$2:$AC1001,MATCH(DATE(P$5,12,1),'Monthly Data'!$A$2:$A1001,0))} -> 13262304
A20: Current portion of debt | B20: {=INDEX('Monthly Data'!$AD$2:$AD1001,MATCH(DATE(B$5,12,1),'Monthly Data'!$A$2:$A1001,0))} -> 0 | C20: {=INDEX('Monthly Data'!$AD$2:$AD1001,MATCH(DATE(C$5,12,1),'Monthly Data'!$A$2:$A1001,0))} -> 0 | D20: {=INDEX('Monthly Data'!$AD$2:$AD1001,MATCH(DATE(D$5,12,1),'Monthly Data'!$A$2:$A1001,0))} -> 0 | E20: {=INDEX('Monthly Data'!$AD$2:$AD1001,MATCH(DATE(E$5,12,1),'Monthly Data'!$A$2:$A1001,0))} -> 0 | F20: {=INDEX('Monthly Data'!$AD$2:$AD1001,MATCH(DATE(F$5,12,1),'Monthly Data'!$A$2:$A1001,0))} -> 0 | G20: {=INDEX('Monthly Data'!$AD$2:$AD1001,MATCH(DATE(G$5,12,1),'Monthly Data'!$A$2:$A1001,0))} -> 5000000 | H20: {=INDEX('Monthly Data'!$AD$2:$AD1001,MATCH(DATE(H$5,12,1),'Monthly Data'!$A$2:$A1001,0))} -> 0 | I20: {=INDEX('Monthly Data'!$AD$2:$AD1001,MATCH(DATE(I$5,12,1),'Monthly Data'!$A$2:$A1001,0))} -> 0 | ... P20: {=INDEX('Monthly Data'!$AD$2:$AD1001,MATCH(DATE(P$5,12,1),'Monthly Data'!$A$2:$A1001,0))} -> 7000000
A21: TOTAL CURRENT LIABILITIES | B21: =SUM(B17:B20) -> 101952 | C21: =SUM(C17:C20) -> 238199 | D21: =SUM(D17:D20) -> 593281 | E21: =SUM(E17:E20) -> 1226192 | F21: =SUM(F17:F20) -> 4265890 | G21: =SUM(G17:G20) -> 14387534 | H21: =SUM(H17:H20) -> 17970644 | I21: =SUM(I17:I20) -> 27883452 | ... P21: =SUM(P17:P20) -> 86756321
A22: Long-term venture debt | B22: =B32-B20 -> 0 | C22: =C32-C20 -> 0 | D22: =D32-D20 -> 0 | E22: =E32-E20 -> 0 | F22: =F32-F20 -> 22000000 | G22: =G32-G20 -> 57000000 | H22: =H32-H20 -> 57000000 | I22: =I32-I20 -> 97000000 | ... P22: =P32-P20 -> 0
A23: TOTAL LIABILITIES | B23: =SUM(B21:B22) -> 101952 | C23: =SUM(C21:C22) -> 238199 | D23: =SUM(D21:D22) -> 593281 | E23: =SUM(E21:E22) -> 1226192 | F23: =SUM(F21:F22) -> 26265890 | G23: =SUM(G21:G22) -> 71387534 | H23: =SUM(H21:H22) -> 74970644 | I23: =SUM(I21:I22) -> 124883452 | ... P23: =SUM(P21:P22) -> 86756321
A25: STOCKHOLDERS EQUITY
A26: Additional paid-in capital | B26: =0+'Cash Flow'!B24+'Income Statement'!B26 -> 6040000 | C26: ='Balance Sheet'!B26+'Cash Flow'!C24+'Income Statement'!C26 -> 6140000 | D26: ='Balance Sheet'!C26+'Cash Flow'!D24+'Income Statement'!D26 -> 30380000 | E26: ='Balance Sheet'!D26+'Cash Flow'!E24+'Income Statement'!E26 -> 30830000 | F26: ='Balance Sheet'!E26+'Cash Flow'!F24+'Income Statement'!F26 -> 91580000 | G26: ='Balance Sheet'!F26+'Cash Flow'!G24+'Income Statement'!G26 -> 93580000 | H26: ='Balance Sheet'!G26+'Cash Flow'!H24+'Income Statement'!H26 -> 207580000 | I26: ='Balance Sheet'!H26+'Cash Flow'!I24+'Income Statement'!I26 -> 214580000 | J26: ='Balance Sheet'!I26+'Cash Flow'!J24+'Income Statement'!J26 -> 381860536 | ... P26: ='Balance Sheet'!O26+'Cash Flow'!P24+'Income Statement'!P26 -> 953194239
A27: Accumulated deficit / retained earnings | B27: =0+'Income Statement'!B36 -> -1920000 | C27: ='Balance Sheet'!B27+'Income Statement'!C36 -> -4570000 | D27: ='Balance Sheet'!C27+'Income Statement'!D36 -> -8870000 | E27: ='Balance Sheet'!D27+'Income Statement'!E36 -> -14552000 | F27: ='Balance Sheet'!E27+'Income Statement'!F36 -> -35637000 | G27: ='Balance Sheet'!F27+'Income Statement'!G36 -> -75637000 | H27: ='Balance Sheet'!G27+'Income Statement'!H36 -> -138074500 | I27: ='Balance Sheet'!H27+'Income Statement'!I36 -> -228139500 | J27: ='Balance Sheet'!I27+'Income Statement'!J36 -> -374551906 | ... P27: ='Balance Sheet'!O27+'Income Statement'!P36 -> -816581272
A28: TOTAL STOCKHOLDERS EQUITY | B28: =SUM(B26:B27) -> 4120000 | C28: =SUM(C26:C27) -> 1570000 | D28: =SUM(D26:D27) -> 21510000 | E28: =SUM(E26:E27) -> 16278000 | F28: =SUM(F26:F27) -> 55943000 | G28: =SUM(G26:G27) -> 17943000 | H28: =SUM(H26:H27) -> 69505500 | I28: =SUM(I26:I27) -> -13559500 | ... P28: =SUM(P26:P27) -> 136612967
A30: TOTAL LIABILITIES AND EQUITY | B30: =B23+B28 -> 4221952 | C30: =C23+C28 -> 1808199 | D30: =D23+D28 -> 22103281 | E30: =E23+E28 -> 17504192 | F30: =F23+F28 -> 82208890 | G30: =G23+G28 -> 89330534 | H30: =H23+H28 -> 144476144 | I30: =I23+I28 -> 111323952 | ... P30: =P23+P28 -> 223369288
A31: Balance sheet difference (must = 0) | B31: =B14-B30 -> 0 | C31: =C14-C30 -> 0 | D31: =D14-D30 -> 0 | E31: =E14-E30 -> 0 | F31: =F14-F30 -> 0 | G31: =G14-G30 -> 0 | H31: =H14-H30 -> 0 | I31: =I14-I30 -> 0 | ... P31: =P14-P30 -> 0
A32: Total debt (for interest calculation) | B32: {=INDEX('Monthly Data'!$AE$2:$AE1001,MATCH(DATE(B$5,12,1),'Monthly Data'!$A$2:$A1001,0))} -> 0 | C32: {=INDEX('Monthly Data'!$AE$2:$AE1001,MATCH(DATE(C$5,12,1),'Monthly Data'!$A$2:$A1001,0))} -> 0 | D32: {=INDEX('Monthly Data'!$AE$2:$AE1001,MATCH(DATE(D$5,12,1),'Monthly Data'!$A$2:$A1001,0))} -> 0 | E32: {=INDEX('Monthly Data'!$AE$2:$AE1001,MATCH(DATE(E$5,12,1),'Monthly Data'!$A$2:$A1001,0))} -> 0 | F32: {=INDEX('Monthly Data'!$AE$2:$AE1001,MATCH(DATE(F$5,12,1),'Monthly Data'!$A$2:$A1001,0))} -> 22000000 | G32: {=INDEX('Monthly Data'!$AE$2:$AE1001,MATCH(DATE(G$5,12,1),'Monthly Data'!$A$2:$A1001,0))} -> 62000000 | H32: {=INDEX('Monthly Data'!$AE$2:$AE1001,MATCH(DATE(H$5,12,1),'Monthly Data'!$A$2:$A1001,0))} -> 57000000 | I32: {=INDEX('Monthly Data'!$AE$2:$AE1001,MATCH(DATE(I$5,12,1),'Monthly Data'!$A$2:$A1001,0))} -> 97000000 | ... P32: {=INDEX('Monthly Data'!$AE$2:$AE1001,MATCH(DATE(P$5,12,1),'Monthly Data'!$A$2:$A1001,0))} -> 7000000

Sheet Monthly Data
A1: Month | B1: Fiscal year | C1: THX-101 prescription fills | D1: Institutional research clients | E1: THX-101 licensed GLP-1 revenue ($) | F1: Research services revenue ($) | G1: Licensing/collaboration revenue ($) | H1: THX-101 manufacturing & distribution ($) | I1: THX-101 partner licensing royalty ($) | J1: Research service delivery costs ($) | K1: License service delivery costs ($) | L1: THX-202 muscle research & trials ($) | M1: THX-303 bone discovery R&D ($) | N1: Sales and marketing expense ($) | O1: General & administration expense ($) | P1: Noncash stock compensation ($) | Q1: Depreciation & amortization ($) | R1: Venture debt interest expense ($) | S1: Income tax expense ($) | T1: Equipment/facilities capex ($) | U1: Equity funding proceeds ($) | V1: New debt proceeds ($) | W1: Debt principal repayments ($) | X1: Accounts receivable, month-end ($) | Y1: Inventory, month-end ($) | Z1: Prepaids, month-end ($) | AA1: Accounts payable, month-end ($) | AB1: Accrued expenses, month-end ($) | AC1: Deferred contract revenue, month-end ($) | AD1: Current debt, month-end ($) | AE1: Total debt, month-end ($) | AF1: Cash, month-end ($) | AG1: Cash change before equity ($) | AH1: THX-202 active treated patients | AI1: THX-202 commercial revenue ($) | AJ1: THX-202 commercial delivery costs ($) | AL1: FY2026 methodology
A2: 43101 | B2: =YEAR(A2) -> 2018 | C2: ='Revenue & Demand'!C166 -> 0 | D2: ='Revenue & Demand'!F166 -> 0 | E2: ='Revenue & Demand'!E166 -> 0 | F2: ='Revenue & Demand'!H166 -> 0 | G2: ='Revenue & Demand'!J166 -> 0 | H2: ='Manufacturing & Production'!F206 -> 0 | I2: ='Manufacturing & Production'!G206 -> 0 | J2: ='Workforce & Expenses'!M258 -> 0 | K2: ='Manufacturing & Production'!K206 -> 0 | L2: ='Clinical Trials & R&D'!F206 -> 96895 | M2: ='Clinical Trials & R&D'!I206 -> 0 | N2: ='Workforce & Expenses'!P258 -> 3632 | O2: ='Workforce & Expenses'!S258 -> 49115 | P2: ='Funding & Cap'!F61 -> 3009 | Q2: ='Working Capital & Assets'!B5 -> 2500 | R2: ='Funding & Cap'!H61 -> 0 | S2: ='Working Capital & Assets'!C5 -> 0 | T2: ='Working Capital & Assets'!D5 -> 22183 | U2: ='Funding & Cap'!B61 -> 6000000 | V2: ='Funding & Cap'!C61 -> 0 | W2: ='Funding & Cap'!D61 -> 0 | X2: ='Working Capital & Assets'!E5 -> 0 | Y2: ='Working Capital & Assets'!F5 -> 0 | Z2: ='Working Capital & Assets'!G5 -> 0 | AA2: ='Working Capital & Assets'!H5 -> 873 | AB2: ='Working Capital & Assets'!I5 -> 8541 | AC2: ='Working Capital & Assets'!J5 -> 0 | AD2: =MIN(AE2,SUMIFS($W$2:$W$181,$A$2:$A$181,">"&A2,$A$2:$A$181,"<="&EDATE(A2,12))+IF(AND(DATE(2033,12,1)>A2,DATE(2033,12,1)<=EDATE(A2,12)),'Funding & Cap'!$B$200,0)) -> 0 | AE2: ='Funding & Cap'!Q61 -> 0 | AF2: =AG2+U2 -> 5837589 | AG2: =SUM(E2:G2)-SUM(H2:S2)+P2+Q2-X2-Y2-Z2+AA2+AB2+AC2-T2+V2-W2 -> -162411 | AH2: ='Revenue & Demand'!P166 -> 0 | AI2: ='Revenue & Demand'!Q166 -> 0 | AJ2: ='Manufacturing & Production'!J206 -> 0 | AL2: Jan–Sep 2026 are fixed synthetic actuals, entered on historical operating schedules.
A3: 43132 | B3: =YEAR(A3) -> 2018 | C3: ='Revenue & Demand'!C167 -> 0 | D3: ='Revenue & Demand'!F167 -> 0 | E3: ='Revenue & Demand'!E167 -> 0 | F3: ='Revenue & Demand'!H167 -> 0 | G3: ='Revenue & Demand'!J167 -> 0 | H3: ='Manufacturing & Production'!F207 -> 0 | I3: ='Manufacturing & Production'!G207 -> 0 | J3: ='Workforce & Expenses'!M259 -> 0 | K3: ='Manufacturing & Production'!K207 -> 0 | L3: ='Clinical Trials & R&D'!F207 -> 99034 | M3: ='Clinical Trials & R&D'!I207 -> 0 | N3: ='Workforce & Expenses'!P259 -> 4487 | O3: ='Workforce & Expenses'!S259 -> 50150 | P3: ='Funding & Cap'!F62 -> 3068 | Q3: ='Working Capital & Assets'!B6 -> 2500 | R3: ='Funding & Cap'!H62 -> 0 | S3: ='Working Capital & Assets'!C6 -> 0 | T3: ='Working Capital & Assets'!D6 -> 22457 | U3: ='Funding & Cap'!B62 -> 0 | V3: ='Funding & Cap'!C62 -> 0 | W3: ='Funding & Cap'!D62 -> 0 | X3: ='Working Capital & Assets'!E6 -> 0 | Y3: ='Working Capital & Assets'!F6 -> 0 | Z3: ='Working Capital & Assets'!G6 -> 0 | AA3: ='Working Capital & Assets'!H6 -> 1723 | AB3: ='Working Capital & Assets'!I6 -> 16859 | AC3: ='Working Capital & Assets'!J6 -> 0 | AD3: =MIN(AE3,SUMIFS($W$2:$W$181,$A$2:$A$181,">"&A3,$A$2:$A$181,"<="&EDATE(A3,12))+IF(AND(DATE(2033,12,1)>A3,DATE(2033,12,1)<=EDATE(A3,12)),'Funding & Cap'!$B$200,0)) -> 0 | AE3: ='Funding & Cap'!Q62 -> 0 | AF3: =AF2+AG3+U3 -> 5670629 | AG3: =SUM(E3:G3)-SUM(H3:S3)+P3+Q3-(X3-X2)-(Y3-Y2)-(Z3-Z2)+(AA3-AA2)+(AB3-AB2)+(AC3-AC2)-T3+V3-W3 -> -166960 | AH3: ='Revenue & Demand'!P167 -> 0 | AI3: ='Revenue & Demand'!Q167 -> 0 | AJ3: ='Manufacturing & Production'!J207 -> 0 | AL3: Oct–Dec 2026 remain projections, rebased to YTD operating performance.
A4: 43160 | B4: =YEAR(A4) -> 2018 | C4: ='Revenue & Demand'!C168 -> 0 | D4: ='Revenue & Demand'!F168 -> 0 | E4: ='Revenue & Demand'!E168 -> 0 | F4: ='Revenue & Demand'!H168 -> 0 | G4: ='Revenue & Demand'!J168 -> 0 | H4: ='Manufacturing & Production'!F208 -> 0 | I4: ='Manufacturing & Production'!G208 -> 0 | J4: ='Workforce & Expenses'!M260 -> 0 | K4: ='Manufacturing & Production'!K208 -> 0 | L4: ='Clinical Trials & R&D'!F208 -> 99028 | M4: ='Clinical Trials & R&D'!I208 -> 0 | N4: ='Workforce & Expenses'!P260 -> 5342 | O4: ='Workforce & Expenses'!S260 -> 50741 | P4: ='Funding & Cap'!F63 -> 3127 | Q4: ='Working Capital & Assets'!B7 -> 2500 | R4: ='Funding & Cap'!H63 -> 0 | S4: ='Working Capital & Assets'!C7 -> 0 | T4: ='Working Capital & Assets'!D7 -> 55595 | U4: ='Funding & Cap'!B63 -> 0 | V4: ='Funding & Cap'!C63 -> 0 | W4: ='Funding & Cap'!D63 -> 0 | X4: ='Working Capital & Assets'!E7 -> 0 | Y4: ='Working Capital & Assets'!F7 -> 0 | Z4: ='Working Capital & Assets'!G7 -> 0 | AA4: ='Working Capital & Assets'!H7 -> 2533 | AB4: ='Working Capital & Assets'!I7 -> 24790 | AC4: ='Working Capital & Assets'!J7 -> 0 | AD4: =MIN(AE4,SUMIFS($W$2:$W$181,$A$2:$A$181,">"&A4,$A$2:$A$181,"<="&EDATE(A4,12))+IF(AND(DATE(2033,12,1)>A4,DATE(2033,12,1)<=EDATE(A4,12)),'Funding & Cap'!$B$200,0)) -> 0 | AE4: ='Funding & Cap'!Q63 -> 0 | AF4: =AF3+AG4+U4 -> 5468664 | AG4: =SUM(E4:G4)-SUM(H4:S4)+P4+Q4-(X4-X3)-(Y4-Y3)-(Z4-Z3)+(AA4-AA3)+(AB4-AB3)+(AC4-AC3)-T4+V4-W4 -> -201965 | AH4: ='Revenue & Demand'!P168 -> 0 | AI4: ='Revenue & Demand'!Q168 -> 0 | AJ4: ='Manufacturing & Production'!J208 -> 0 | AL4: 2026 annual statements = nine completed months + three forecast months.
A5: 43191 | B5: =YEAR(A5) -> 2018 | C5: ='Revenue & Demand'!C169 -> 0 | D5: ='Revenue & Demand'!F169 -> 0 | E5: ='Revenue & Demand'!E169 -> 0 | F5: ='Revenue & Demand'!H169 -> 0 | G5: ='Revenue & Demand'!J169 -> 0 | H5: ='Manufacturing & Production'!F209 -> 0 | I5: ='Manufacturing & Production'!G209 -> 0 | J5: ='Workforce & Expenses'!M261 -> 0 | K5: ='Manufacturing & Production'!K209 -> 0 | L5: ='Clinical Trials & R&D'!F209 -> 97167 | M5: ='Clinical Trials & R&D'!I209 -> 0 | N5: ='Workforce & Expenses'!P261 -> 6197 | O5: ='Workforce & Expenses'!S261 -> 50820 | P5: ='Funding & Cap'!F64 -> 3186 | Q5: ='Working Capital & Assets'!B8 -> 2500 | R5: ='Funding & Cap'!H64 -> 0 | S5: ='Working Capital & Assets'!C8 -> 0 | T5: ='Working Capital & Assets'!D8 -> 23005 | U5: ='Funding & Cap'!B64 -> 0 | V5: ='Funding & Cap'!C64 -> 0 | W5: ='Funding & Cap'!D64 -> 0 | X5: ='Working Capital & Assets'!E8 -> 0 | Y5: ='Working Capital & Assets'!F8 -> 0 | Z5: ='Working Capital & Assets'!G8 -> 0 | AA5: ='Working Capital & Assets'!H8 -> 3298 | AB5: ='Working Capital & Assets'!I8 -> 32275 | AC5: ='Working Capital & Assets'!J8 -> 0 | AD5: =MIN(AE5,SUMIFS($W$2:$W$181,$A$2:$A$181,">"&A5,$A$2:$A$181,"<="&EDATE(A5,12))+IF(AND(DATE(2033,12,1)>A5,DATE(2033,12,1)<=EDATE(A5,12)),'Funding & Cap'!$B$200,0)) -> 0 | AE5: ='Funding & Cap'!Q64 -> 0 | AF5: =AF4+AG5+U5 -> 5299725 | AG5: =SUM(E5:G5)-SUM(H5:S5)+P5+Q5-(X5-X4)-(Y5-Y4)-(Z5-Z4)+(AA5-AA4)+(AB5-AB4)+(AC5-AC4)-T5+V5-W5 -> -168939 | AH5: ='Revenue & Demand'!P169 -> 0 | AI5: ='Revenue & Demand'!Q169 -> 0 | AJ5: ='Manufacturing & Production'!J209 -> 0
A6: 43221 | B6: =YEAR(A6) -> 2018 | C6: ='Revenue & Demand'!C170 -> 0 | D6: ='Revenue & Demand'!F170 -> 0 | E6: ='Revenue & Demand'!E170 -> 0 | F6: ='Revenue & Demand'!H170 -> 0 | G6: ='Revenue & Demand'!J170 -> 0 | H6: ='Manufacturing & Production'!F210 -> 0 | I6: ='Manufacturing & Production'!G210 -> 0 | J6: ='Workforce & Expenses'!M262 -> 0 | K6: ='Manufacturing & Production'!K210 -> 0 | L6: ='Clinical Trials & R&D'!F210 -> 94233 | M6: ='Clinical Trials & R&D'!I210 -> 0 | N6: ='Workforce & Expenses'!P262 -> 7051 | O6: ='Workforce & Expenses'!S262 -> 50454 | P6: ='Funding & Cap'!F65 -> 3245 | Q6: ='Working Capital & Assets'!B9 -> 2500 | R6: ='Funding & Cap'!H65 -> 0 | S6: ='Working Capital & Assets'!C9 -> 0 | T6: ='Working Capital & Assets'!D9 -> 23279 | U6: ='Funding & Cap'!B65 -> 0 | V6: ='Funding & Cap'!C65 -> 0 | W6: ='Funding & Cap'!D65 -> 0 | X6: ='Working Capital & Assets'!E9 -> 0 | Y6: ='Working Capital & Assets'!F9 -> 0 | Z6: ='Working Capital & Assets'!G9 -> 0 | AA6: ='Working Capital & Assets'!H9 -> 4023 | AB6: ='Working Capital & Assets'!I9 -> 39374 | AC6: ='Working Capital & Assets'!J9 -> 0 | AD6: =MIN(AE6,SUMIFS($W$2:$W$181,$A$2:$A$181,">"&A6,$A$2:$A$181,"<="&EDATE(A6,12))+IF(AND(DATE(2033,12,1)>A6,DATE(2033,12,1)<=EDATE(A6,12)),'Funding & Cap'!$B$200,0)) -> 0 | AE6: ='Funding & Cap'!Q65 -> 0 | AF6: =AF5+AG6+U6 -> 5132532 | AG6: =SUM(E6:G6)-SUM(H6:S6)+P6+Q6-(X6-X5)-(Y6-Y5)-(Z6-Z5)+(AA6-AA5)+(AB6-AB5)+(AC6-AC5)-T6+V6-W6 -> -167193 | AH6: ='Revenue & Demand'!P170 -> 0 | AI6: ='Revenue & Demand'!Q170 -> 0 | AJ6: ='Manufacturing & Production'!J210 -> 0
A7: 43252 | B7: =YEAR(A7) -> 2018 | C7: ='Revenue & Demand'!C171 -> 0 | D7: ='Revenue & Demand'!F171 -> 0 | E7: ='Revenue & Demand'!E171 -> 0 | F7: ='Revenue & Demand'!H171 -> 0 | G7: ='Revenue & Demand'!J171 -> 0 | H7: ='Manufacturing & Production'!F211 -> 0 | I7: ='Manufacturing & Production'!G211 -> 0 | J7: ='Workforce & Expenses'!M263 -> 0 | K7: ='Manufacturing & Production'!K211 -> 0 | L7: ='Clinical Trials & R&D'!F211 -> 91299 | M7: ='Clinical Trials & R&D'!I211 -> 0 | N7: ='Workforce & Expenses'!P263 -> 7906 | O7: ='Workforce & Expenses'!S263 -> 49833 | P7: ='Funding & Cap'!F66 -> 3304 | Q7: ='Working Capital & Assets'!B10 -> 2500 | R7: ='Funding & Cap'!H66 -> 0 | S7: ='Working Capital & Assets'!C10 -> 0 | T7: ='Working Capital & Assets'!D10 -> 23552 | U7: ='Funding & Cap'!B66 -> 0 | V7: ='Funding & Cap'!C66 -> 0 | W7: ='Funding & Cap'!D66 -> 0 | X7: ='Working Capital & Assets'!E10 -> 0 | Y7: ='Working Capital & Assets'!F10 -> 0 | Z7: ='Working Capital & Assets'!G10 -> 0 | AA7: ='Working Capital & Assets'!H10 -> 4726 | AB7: ='Working Capital & Assets'!I10 -> 46250 | AC7: ='Working Capital & Assets'!J10 -> 0 | AD7: =MIN(AE7,SUMIFS($W$2:$W$181,$A$2:$A$181,">"&A7,$A$2:$A$181,"<="&EDATE(A7,12))+IF(AND(DATE(2033,12,1)>A7,DATE(2033,12,1)<=EDATE(A7,12)),'Funding & Cap'!$B$200,0)) -> 0 | AE7: ='Funding & Cap'!Q66 -> 0 | AF7: =AF6+AG7+U7 -> 4967521 | AG7: =SUM(E7:G7)-SUM(H7:S7)+P7+Q7-(X7-X6)-(Y7-Y6)-(Z7-Z6)+(AA7-AA6)+(AB7-AB6)+(AC7-AC6)-T7+V7-W7 -> -165011 | AH7: ='Revenue & Demand'!P171 -> 0 | AI7: ='Revenue & Demand'!Q171 -> 0 | AJ7: ='Manufacturing & Production'!J211 -> 0
A8: 43282 | B8: =YEAR(A8) -> 2018 | C8: ='Revenue & Demand'!C172 -> 0 | D8: ='Revenue & Demand'!F172 -> 0 | E8: ='Revenue & Demand'!E172 -> 0 | F8: ='Revenue & Demand'!H172 -> 0 | G8: ='Revenue & Demand'!J172 -> 0 | H8: ='Manufacturing & Production'!F212 -> 0 | I8: ='Manufacturing & Production'!G212 -> 0 | J8: ='Workforce & Expenses'!M264 -> 0 | K8: ='Manufacturing & Production'!K212 -> 0 | L8: ='Clinical Trials & R&D'!F212 -> 89438 | M8: ='Clinical Trials & R&D'!I212 -> 0 | N8: ='Workforce & Expenses'!P264 -> 8761 | O8: ='Workforce & Expenses'!S264 -> 49211 | P8: ='Funding & Cap'!F67 -> 3363 | Q8: ='Working Capital & Assets'!B11 -> 2500 | R8: ='Funding & Cap'!H67 -> 0 | S8: ='Working Capital & Assets'!C11 -> 0 | T8: ='Working Capital & Assets'!D11 -> 23826 | U8: ='Funding & Cap'!B67 -> 0 | V8: ='Funding & Cap'!C67 -> 0 | W8: ='Funding & Cap'!D67 -> 0 | X8: ='Working Capital & Assets'!E11 -> 0 | Y8: ='Working Capital & Assets'!F11 -> 0 | Z8: ='Working Capital & Assets'!G11 -> 0 | AA8: ='Working Capital & Assets'!H11 -> 5429 | AB8: ='Working Capital & Assets'!I11 -> 53126 | AC8: ='Working Capital & Assets'!J11 -> 0 | AD8: =MIN(AE8,SUMIFS($W$2:$W$181,$A$2:$A$181,">"&A8,$A$2:$A$181,"<="&EDATE(A8,12))+IF(AND(DATE(2033,12,1)>A8,DATE(2033,12,1)<=EDATE(A8,12)),'Funding & Cap'!$B$200,0)) -> 0 | AE8: ='Funding & Cap'!Q67 -> 0 | AF8: =AF7+AG8+U8 -> 4803864 | AG8: =SUM(E8:G8)-SUM(H8:S8)+P8+Q8-(X8-X7)-(Y8-Y7)-(Z8-Z7)+(AA8-AA7)+(AB8-AB7)+(AC8-AC7)-T8+V8-W8 -> -163657 | AH8: ='Revenue & Demand'!P172 -> 0 | AI8: ='Revenue & Demand'!Q172 -> 0 | AJ8: ='Manufacturing & Production'!J212 -> 0
A9: 43313 | B9: =YEAR(A9) -> 2018 | C9: ='Revenue & Demand'!C173 -> 0 | D9: ='Revenue & Demand'!F173 -> 0 | E9: ='Revenue & Demand'!E173 -> 0 | F9: ='Revenue & Demand'!H173 -> 0 | G9: ='Revenue & Demand'!J173 -> 0 | H9: ='Manufacturing & Production'!F213 -> 0 | I9: ='Manufacturing & Production'!G213 -> 0 | J9: ='Workforce & Expenses'!M265 -> 0 | K9: ='Manufacturing & Production'!K213 -> 0 | L9: ='Clinical Trials & R&D'!F213 -> 89433 | M9: ='Clinical Trials & R&D'!I213 -> 0 | N9: ='Workforce & Expenses'!P265 -> 9615 | O9: ='Workforce & Expenses'!S265 -> 48845 | P9: ='Funding & Cap'!F68 -> 3422 | Q9: ='Working Capital & Assets'!B12 -> 2500 | R9: ='Funding & Cap'!H68 -> 0 | S9: ='Working Capital & Assets'!C12 -> 0 | T9: ='Working Capital & Assets'!D12 -> 24100 | U9: ='Funding & Cap'!B68 -> 0 | V9: ='Funding & Cap'!C68 -> 0 | W9: ='Funding & Cap'!D68 -> 0 | X9: ='Working Capital & Assets'!E12 -> 0 | Y9: ='Working Capital & Assets'!F12 -> 0 | Z9: ='Working Capital & Assets'!G12 -> 0 | AA9: ='Working Capital & Assets'!H12 -> 6154 | AB9: ='Working Capital & Assets'!I12 -> 60225 | AC9: ='Working Capital & Assets'!J12 -> 0 | AD9: =MIN(AE9,SUMIFS($W$2:$W$181,$A$2:$A$181,">"&A9,$A$2:$A$181,"<="&EDATE(A9,12))+IF(AND(DATE(2033,12,1)>A9,DATE(2033,12,1)<=EDATE(A9,12)),'Funding & Cap'!$B$200,0)) -> 0 | AE9: ='Funding & Cap'!Q68 -> 0 | AF9: =AF8+AG9+U9 -> 4639695 | AG9: =SUM(E9:G9)-SUM(H9:S9)+P9+Q9-(X9-X8)-(Y9-Y8)-(Z9-Z8)+(AA9-AA8)+(AB9-AB8)+(AC9-AC8)-T9+V9-W9 -> -164169 | AH9: ='Revenue & Demand'!P173 -> 0 | AI9: ='Revenue & Demand'!Q173 -> 0 | AJ9: ='Manufacturing & Production'!J213 -> 0
A10: 43344 | B10: =YEAR(A10) -> 2018 | C10: ='Revenue & Demand'!C174 -> 0 | D10: ='Revenue & Demand'!F174 -> 0 | E10: ='Revenue & Demand'!E174 -> 0 | F10: ='Revenue & Demand'!H174 -> 0 | G10: ='Revenue & Demand'!J174 -> 0 | H10: ='Manufacturing & Production'!F214 -> 0 | I10: ='Manufacturing & Production'!G214 -> 0 | J10: ='Workforce & Expenses'!M266 -> 0 | K10: ='Manufacturing & Production'!K214 -> 0 | L10: ='Clinical Trials & R&D'!F214 -> 91572 | M10: ='Clinical Trials & R&D'!I214 -> 0 | N10: ='Workforce & Expenses'!P266 -> 10470 | O10: ='Workforce & Expenses'!S266 -> 48924 | P10: ='Funding & Cap'!F69 -> 3481 | Q10: ='Working Capital & Assets'!B13 -> 2500 | R10: ='Funding & Cap'!H69 -> 0 | S10: ='Working Capital & Assets'!C13 -> 0 | T10: ='Working Capital & Assets'!D13 -> 57238 | U10: ='Funding & Cap'!B69 -> 0 | V10: ='Funding & Cap'!C69 -> 0 | W10: ='Funding & Cap'!D69 -> 0 | X10: ='Working Capital & Assets'!E13 -> 0 | Y10: ='Working Capital & Assets'!F13 -> 0 | Z10: ='Working Capital & Assets'!G13 -> 0 | AA10: ='Working Capital & Assets'!H13 -> 6919 | AB10: ='Working Capital & Assets'!I13 -> 67710 | AC10: ='Working Capital & Assets'!J13 -> 0 | AD10: =MIN(AE10,SUMIFS($W$2:$W$181,$A$2:$A$181,">"&A10,$A$2:$A$181,"<="&EDATE(A10,12))+IF(AND(DATE(2033,12,1)>A10,DATE(2033,12,1)<=EDATE(A10,12)),'Funding & Cap'!$B$200,0)) -> 0 | AE10: ='Funding & Cap'!Q69 -> 0 | AF10: =AF9+AG10+U10 -> 4439741 | AG10: =SUM(E10:G10)-SUM(H10:S10)+P10+Q10-(X10-X9)-(Y10-Y9)-(Z10-Z9)+(AA10-AA9)+(AB10-AB9)+(AC10-AC9)-T10+V10-W10 -> -199954 | AH10: ='Revenue & Demand'!P174 -> 0 | AI10: ='Revenue & Demand'!Q174 -> 0 | AJ10: ='Manufacturing & Production'!J214 -> 0
